<?xml version="1.0" encoding="utf-8"?>
<!-- =================================================================================== -->
<!-- |    This document was autogenerated by xacro from custom_robots.urdf.xacro       | -->
<!-- |    EDITING THIS FILE BY HAND IS NOT RECOMMENDED                                 | -->
<!-- =================================================================================== -->
<robot name="custom_robots">
  <material name="black">
    <color rgba="0.0 0.0 0.0 1.0"/>
  </material>
  <material name="blue">
    <color rgba="0.0 0.0 0.8 1.0"/>
  </material>
  <material name="green">
    <color rgba="0.0 0.8 0.0 1.0"/>
  </material>
  <material name="grey_">
    <color rgba="0.2 0.2 0.2 1.0"/>
  </material>
  <material name="orange">
    <color rgba="1.0 0.423529411765 0.0392156862745 1.0"/>
  </material>
  <material name="brown">
    <color rgba="0.870588235294 0.811764705882 0.764705882353 1.0"/>
  </material>
  <material name="red">
    <color rgba="0.8 0.0 0.0 1.0"/>
  </material>
  <material name="white">
    <color rgba="1.0 1.0 1.0 1.0"/>
  </material>
  <material name="metal">
    <color rgba="0.768627450980392 0.749019607843137 0.729411764705882 1"/>
  </material>
  <material name="metal_grey">
    <color rgba="0.501960784313725 0.501960784313725 0.501960784313725 1"/>
  </material>
  <material name="metal_white">
    <color rgba="0.866666666666667 0.866666666666667 0.890196078431373 1"/>
  </material>
  <link name="world"/>
  <joint name="indy0_joint_world" type="fixed">
    <parent link="world"/>
    <child link="indy0_link0"/>
    <origin rpy="0 0 0" xyz="0 0.5 0"/>
  </joint>
  <!-- <material name="grey"> <color rgba="0.5 0.5 0.5 1"/> </material> -->
  <link name="indy0_link0">
    <visual>
      <origin rpy="0 0 0" xyz="0 0 0"/>
      <geometry>
        <mesh filename="package://indy7_description/meshes/stl/Indy7_0.stl"/>
      </geometry>
      <material name="metal_grey"/>
    </visual>
    <collision>
      <origin rpy="0 0 0" xyz="0 0 0"/>
      <geometry>
        <cylinder length="0.075" radius="0.102"/>
      </geometry>
    </collision>
    <inertial>
      <origin rpy="0 0 0" xyz="0 0 0"/>
      <mass value="1.59306955"/>
      <inertia ixx="+0.00572623" ixy="+0.00000251" ixz="-0.00011380" iyy="+0.00558959" iyz="-0.00000014" izz="+0.00966674"/>
    </inertial>
  </link>
  <link name="indy0_link1">
    <visual>
      <origin rpy="0 0 0" xyz="0 0 0"/>
      <geometry>
        <mesh filename="package://indy7_description/meshes/stl/Indy7_1.stl"/>
      </geometry>
      <material name="metal_grey"/>
    </visual>
    <collision>
      <origin rpy="0 0 0" xyz="0 0 0.111"/>
      <geometry>
        <cylinder length="0.222" radius="0.075"/>
      </geometry>
    </collision>
    <collision>
      <origin rpy="1.57079632679 0 0" xyz="0 -0.0545 0.222"/>
      <geometry>
        <cylinder length="0.109" radius="0.075"/>
      </geometry>
    </collision>
    <inertial>
      <origin rpy="0 0 0" xyz="0 0 0"/>
      <mass value="11.8030102"/>
      <inertia ixx="+0.15418559" ixy="-0.00000235" ixz="+0.00001739" iyy="+0.12937017" iyz="-0.04854267" izz="+0.05964415"/>
    </inertial>
  </link>
  <link name="indy0_link2">
    <visual>
      <origin rpy="0 0 0" xyz="0 0 0"/>
      <geometry>
        <mesh filename="package://indy7_description/meshes/stl/Indy7_2.stl"/>
      </geometry>
      <material name="metal_grey"/>
    </visual>
    <collision>
      <origin rpy="1.57079632679 0 -1.57079632679" xyz="-0.225 0 0.09"/>
      <geometry>
        <cylinder length="0.450" radius="0.063"/>
      </geometry>
    </collision>
    <collision>
      <origin rpy="0 0 0" xyz="0 0 0.045"/>
      <geometry>
        <cylinder length="0.09" radius="0.075"/>
      </geometry>
    </collision>
    <collision>
      <origin rpy="0 0 0" xyz="-0.45 0 0.02975 "/>
      <geometry>
        <cylinder length="0.1205" radius="0.045"/>
      </geometry>
    </collision>
    <inertial>
      <origin rpy="0 0 0" xyz="0 0 0"/>
      <mass value="7.99292141"/>
      <inertia ixx="+0.29356980" ixy="-0.00000040" ixz="+0.00001441" iyy="+0.28094142" iyz="+0.03727972" izz="+0.03620609"/>
    </inertial>
  </link>
  <link name="indy0_link3">
    <visual>
      <origin rpy="0 0 0" xyz="0 0 0"/>
      <geometry>
        <mesh filename="package://indy7_description/meshes/stl/Indy7_3.stl"/>
      </geometry>
      <material name="metal_grey"/>
    </visual>
    <collision>
      <origin rpy="1.57079632679 0 -1.57079632679" xyz="-0.1335 0 -0.075"/>
      <geometry>
        <cylinder length="0.267" radius="0.045"/>
      </geometry>
    </collision>
    <collision>
      <origin rpy="0 0 0" xyz="0 0 -0.0375"/>
      <geometry>
        <cylinder length="0.075" radius="0.045"/>
      </geometry>
    </collision>
    <inertial>
      <origin rpy="0 0 0" xyz="0 0 0"/>
      <mass value="2.99134127"/>
      <inertia ixx="+0.03424593" ixy="+0.00000149" ixz="+0.00000724" iyy="+0.03406024" iyz="+0.00186009" izz="+0.00450477"/>
    </inertial>
  </link>
  <link name="indy0_link4">
    <visual>
      <origin rpy="0 0 0" xyz="0 0 0"/>
      <geometry>
        <mesh filename="package://indy7_description/meshes/stl/Indy7_4.stl"/>
      </geometry>
      <material name="metal_grey"/>
    </visual>
    <collision>
      <origin rpy="1.57079632679 0 0" xyz="0 -0.057 0.083"/>
      <geometry>
        <cylinder length="0.114" radius="0.045"/>
      </geometry>
    </collision>
    <collision>
      <origin rpy="1.57079632679 0 0" xyz="0 -0.057 0.083"/>
      <geometry>
        <cylinder length="0.114" radius="0.045"/>
      </geometry>
    </collision>
    <collision>
      <origin rpy="0 0 0" xyz="0 0 0.0415"/>
      <geometry>
        <cylinder length="0.083" radius="0.045"/>
      </geometry>
    </collision>
    <inertial>
      <origin rpy="0 0 0" xyz="0 0 0"/>
      <mass value="2.12317035"/>
      <inertia ixx="+0.00670405" ixy="+0.00000375" ixz="+0.00000150" iyy="+0.00279246" iyz="-0.00127967" izz="+0.00619341"/>
    </inertial>
  </link>
  <link name="indy0_link5">
    <visual>
      <origin rpy="0 0 0" xyz="0 0 0"/>
      <geometry>
        <mesh filename="package://indy7_description/meshes/stl/Indy7_5.stl"/>
      </geometry>
      <material name="metal_grey"/>
    </visual>
    <collision>
      <origin rpy="1.57079632679 0 -1.57079632679" xyz="-0.084 0 0.069"/>
      <geometry>
        <cylinder length="0.168" radius="0.045"/>
      </geometry>
    </collision>
    <collision>
      <origin rpy="0 0 0" xyz="-0 0 0.0345"/>
      <geometry>
        <cylinder length="0.069" radius="0.045"/>
      </geometry>
    </collision>
    <inertial>
      <origin rpy="0 0 0" xyz="0 0 0"/>
      <mass value="2.28865091"/>
      <inertia ixx="+0.00994891" ixy="+0.00000014" ixz="+0.00000321" iyy="+0.00978189" iyz="-0.00093546" izz="+0.00271492"/>
    </inertial>
  </link>
  <link name="indy0_link6">
    <visual>
      <origin rpy="0 0 0" xyz="0 0 0"/>
      <geometry>
        <mesh filename="package://indy7_description/meshes/stl/Indy7_6.stl"/>
      </geometry>
      <material name="metal_grey"/>
    </visual>
    <collision>
      <origin rpy="0 0 0" xyz="0 0 0.03"/>
      <geometry>
        <cylinder length="0.06" radius="0.045"/>
      </geometry>
    </collision>
    <inertial>
      <origin rpy="0 0 0" xyz="0 0 0"/>
      <mass value="0.40083918"/>
      <inertia ixx="0.00043534" ixy="+0.00000013" ixz="-0.00000002" iyy="0.00044549" iyz="+0.00000051" izz="0.00059634"/>
    </inertial>
  </link>
  <link name="indy0_tcp"/>
  <joint name="indy0_joint0" type="revolute">
    <parent link="indy0_link0"/>
    <child link="indy0_link1"/>
    <origin rpy="0 0 0" xyz="0 0 0.0775"/>
    <axis xyz="0 0 1"/>
    <limit effort="10" lower="-3.05432619099" upper="3.05432619099" velocity="1"/>
  </joint>
  <joint name="indy0_joint1" type="revolute">
    <parent link="indy0_link1"/>
    <child link="indy0_link2"/>
    <origin rpy="1.57079632679 1.57079632679 0" xyz="0 -0.10900000 0.22200000"/>
    <axis xyz="0 0 1"/>
    <limit effort="10" lower="-3.05432619099" upper="3.05432619099" velocity="1"/>
  </joint>
  <joint name="indy0_joint2" type="revolute">
    <parent link="indy0_link2"/>
    <child link="indy0_link3"/>
    <origin rpy="0 0 0" xyz="-0.45000000 +0.00000000 -0.03050000"/>
    <axis xyz="0 0 1"/>
    <limit effort="10" lower="-3.05432619099" upper="3.05432619099" velocity="1"/>
  </joint>
  <joint name="indy0_joint3" type="revolute">
    <parent link="indy0_link3"/>
    <child link="indy0_link4"/>
    <origin rpy="-1.57079632679 0 1.57079632679" xyz="-0.26700000 +0.00000000 -0.07500000"/>
    <axis xyz="0 0 1"/>
    <limit effort="10" lower="-3.05432619099" upper="3.05432619099" velocity="1"/>
  </joint>
  <joint name="indy0_joint4" type="revolute">
    <parent link="indy0_link4"/>
    <child link="indy0_link5"/>
    <origin rpy="1.57079632679 1.57079632679 0" xyz="+0.00000000 -0.11400000 +0.08300000"/>
    <axis xyz="0 0 1"/>
    <limit effort="10" lower="-3.05432619099" upper="3.05432619099" velocity="1"/>
  </joint>
  <joint name="indy0_joint5" type="revolute">
    <parent link="indy0_link5"/>
    <child link="indy0_link6"/>
    <origin rpy="-1.57079632679 0 1.57079632679" xyz="-0.16800000 +0.00000000 +0.06900000"/>
    <axis xyz="0 0 1"/>
    <limit effort="10" lower="-3.75245789179" upper="3.75245789179" velocity="1"/>
  </joint>
  <joint name="indy0_tcp" type="fixed">
    <parent link="indy0_link6"/>
    <child link="indy0_tcp"/>
    <origin rpy="0 0 0" xyz="0 0 0.06"/>
  </joint>
  <transmission name="indy0_tran0">
    <type>transmission_interface/SimpleTransmission</type>
    <joint name="indy0_joint0">
      <hardwareInterface>PositionJointInterface</hardwareInterface>
    </joint>
    <actuator name="indy0_motor0">
      <hardwareInterface>PositionJointInterface</hardwareInterface>
      <mechanicalReduction>1</mechanicalReduction>
    </actuator>
  </transmission>
  <transmission name="indy0_tran1">
    <type>transmission_interface/SimpleTransmission</type>
    <joint name="indy0_joint1">
      <hardwareInterface>PositionJointInterface</hardwareInterface>
    </joint>
    <actuator name="indy0_motor1">
      <hardwareInterface>PositionJointInterface</hardwareInterface>
      <mechanicalReduction>1</mechanicalReduction>
    </actuator>
  </transmission>
  <transmission name="indy0_tran2">
    <type>transmission_interface/SimpleTransmission</type>
    <joint name="indy0_joint2">
      <hardwareInterface>PositionJointInterface</hardwareInterface>
    </joint>
    <actuator name="indy0_motor2">
      <hardwareInterface>PositionJointInterface</hardwareInterface>
      <mechanicalReduction>1</mechanicalReduction>
    </actuator>
  </transmission>
  <transmission name="indy0_tran3">
    <type>transmission_interface/SimpleTransmission</type>
    <joint name="indy0_joint3">
      <hardwareInterface>PositionJointInterface</hardwareInterface>
    </joint>
    <actuator name="indy0_motor3">
      <hardwareInterface>PositionJointInterface</hardwareInterface>
      <mechanicalReduction>1</mechanicalReduction>
    </actuator>
  </transmission>
  <transmission name="indy0_tran4">
    <type>transmission_interface/SimpleTransmission</type>
    <joint name="indy0_joint4">
      <hardwareInterface>PositionJointInterface</hardwareInterface>
    </joint>
    <actuator name="indy0_motor4">
      <hardwareInterface>PositionJointInterface</hardwareInterface>
      <mechanicalReduction>1</mechanicalReduction>
    </actuator>
  </transmission>
  <transmission name="indy0_tran5">
    <type>transmission_interface/SimpleTransmission</type>
    <joint name="indy0_joint5">
      <hardwareInterface>PositionJointInterface</hardwareInterface>
    </joint>
    <actuator name="indy0_motor5">
      <hardwareInterface>PositionJointInterface</hardwareInterface>
      <mechanicalReduction>1</mechanicalReduction>
    </actuator>
  </transmission>
  <joint name="indy1_joint_world" type="fixed">
    <parent link="world"/>
    <child link="indy1_link0"/>
    <origin rpy="0 0 0" xyz="0 -0.5 0"/>
  </joint>
  <!-- <material name="grey"> <color rgba="0.5 0.5 0.5 1"/> </material> -->
  <link name="indy1_link0">
    <visual>
      <origin rpy="0 0 0" xyz="0 0 0"/>
      <geometry>
        <mesh filename="package://indy7_description/meshes/stl/Indy7_0.stl"/>
      </geometry>
      <material name="metal_grey"/>
    </visual>
    <collision>
      <origin rpy="0 0 0" xyz="0 0 0"/>
      <geometry>
        <cylinder length="0.075" radius="0.102"/>
      </geometry>
    </collision>
    <inertial>
      <origin rpy="0 0 0" xyz="0 0 0"/>
      <mass value="1.59306955"/>
      <inertia ixx="+0.00572623" ixy="+0.00000251" ixz="-0.00011380" iyy="+0.00558959" iyz="-0.00000014" izz="+0.00966674"/>
    </inertial>
  </link>
  <link name="indy1_link1">
    <visual>
      <origin rpy="0 0 0" xyz="0 0 0"/>
      <geometry>
        <mesh filename="package://indy7_description/meshes/stl/Indy7_1.stl"/>
      </geometry>
      <material name="metal_grey"/>
    </visual>
    <collision>
      <origin rpy="0 0 0" xyz="0 0 0.111"/>
      <geometry>
        <cylinder length="0.222" radius="0.075"/>
      </geometry>
    </collision>
    <collision>
      <origin rpy="1.57079632679 0 0" xyz="0 -0.0545 0.222"/>
      <geometry>
        <cylinder length="0.109" radius="0.075"/>
      </geometry>
    </collision>
    <inertial>
      <origin rpy="0 0 0" xyz="0 0 0"/>
      <mass value="11.8030102"/>
      <inertia ixx="+0.15418559" ixy="-0.00000235" ixz="+0.00001739" iyy="+0.12937017" iyz="-0.04854267" izz="+0.05964415"/>
    </inertial>
  </link>
  <link name="indy1_link2">
    <visual>
      <origin rpy="0 0 0" xyz="0 0 0"/>
      <geometry>
        <mesh filename="package://indy7_description/meshes/stl/Indy7_2.stl"/>
      </geometry>
      <material name="metal_grey"/>
    </visual>
    <collision>
      <origin rpy="1.57079632679 0 -1.57079632679" xyz="-0.225 0 0.09"/>
      <geometry>
        <cylinder length="0.450" radius="0.063"/>
      </geometry>
    </collision>
    <collision>
      <origin rpy="0 0 0" xyz="0 0 0.045"/>
      <geometry>
        <cylinder length="0.09" radius="0.075"/>
      </geometry>
    </collision>
    <collision>
      <origin rpy="0 0 0" xyz="-0.45 0 0.02975 "/>
      <geometry>
        <cylinder length="0.1205" radius="0.045"/>
      </geometry>
    </collision>
    <inertial>
      <origin rpy="0 0 0" xyz="0 0 0"/>
      <mass value="7.99292141"/>
      <inertia ixx="+0.29356980" ixy="-0.00000040" ixz="+0.00001441" iyy="+0.28094142" iyz="+0.03727972" izz="+0.03620609"/>
    </inertial>
  </link>
  <link name="indy1_link3">
    <visual>
      <origin rpy="0 0 0" xyz="0 0 0"/>
      <geometry>
        <mesh filename="package://indy7_description/meshes/stl/Indy7_3.stl"/>
      </geometry>
      <material name="metal_grey"/>
    </visual>
    <collision>
      <origin rpy="1.57079632679 0 -1.57079632679" xyz="-0.1335 0 -0.075"/>
      <geometry>
        <cylinder length="0.267" radius="0.045"/>
      </geometry>
    </collision>
    <collision>
      <origin rpy="0 0 0" xyz="0 0 -0.0375"/>
      <geometry>
        <cylinder length="0.075" radius="0.045"/>
      </geometry>
    </collision>
    <inertial>
      <origin rpy="0 0 0" xyz="0 0 0"/>
      <mass value="2.99134127"/>
      <inertia ixx="+0.03424593" ixy="+0.00000149" ixz="+0.00000724" iyy="+0.03406024" iyz="+0.00186009" izz="+0.00450477"/>
    </inertial>
  </link>
  <link name="indy1_link4">
    <visual>
      <origin rpy="0 0 0" xyz="0 0 0"/>
      <geometry>
        <mesh filename="package://indy7_description/meshes/stl/Indy7_4.stl"/>
      </geometry>
      <material name="metal_grey"/>
    </visual>
    <collision>
      <origin rpy="1.57079632679 0 0" xyz="0 -0.057 0.083"/>
      <geometry>
        <cylinder length="0.114" radius="0.045"/>
      </geometry>
    </collision>
    <collision>
      <origin rpy="1.57079632679 0 0" xyz="0 -0.057 0.083"/>
      <geometry>
        <cylinder length="0.114" radius="0.045"/>
      </geometry>
    </collision>
    <collision>
      <origin rpy="0 0 0" xyz="0 0 0.0415"/>
      <geometry>
        <cylinder length="0.083" radius="0.045"/>
      </geometry>
    </collision>
    <inertial>
      <origin rpy="0 0 0" xyz="0 0 0"/>
      <mass value="2.12317035"/>
      <inertia ixx="+0.00670405" ixy="+0.00000375" ixz="+0.00000150" iyy="+0.00279246" iyz="-0.00127967" izz="+0.00619341"/>
    </inertial>
  </link>
  <link name="indy1_link5">
    <visual>
      <origin rpy="0 0 0" xyz="0 0 0"/>
      <geometry>
        <mesh filename="package://indy7_description/meshes/stl/Indy7_5.stl"/>
      </geometry>
      <material name="metal_grey"/>
    </visual>
    <collision>
      <origin rpy="1.57079632679 0 -1.57079632679" xyz="-0.084 0 0.069"/>
      <geometry>
        <cylinder length="0.168" radius="0.045"/>
      </geometry>
    </collision>
    <collision>
      <origin rpy="0 0 0" xyz="-0 0 0.0345"/>
      <geometry>
        <cylinder length="0.069" radius="0.045"/>
      </geometry>
    </collision>
    <inertial>
      <origin rpy="0 0 0" xyz="0 0 0"/>
      <mass value="2.28865091"/>
      <inertia ixx="+0.00994891" ixy="+0.00000014" ixz="+0.00000321" iyy="+0.00978189" iyz="-0.00093546" izz="+0.00271492"/>
    </inertial>
  </link>
  <link name="indy1_link6">
    <visual>
      <origin rpy="0 0 0" xyz="0 0 0"/>
      <geometry>
        <mesh filename="package://indy7_description/meshes/stl/Indy7_6.stl"/>
      </geometry>
      <material name="metal_grey"/>
    </visual>
    <collision>
      <origin rpy="0 0 0" xyz="0 0 0.03"/>
      <geometry>
        <cylinder length="0.06" radius="0.045"/>
      </geometry>
    </collision>
    <inertial>
      <origin rpy="0 0 0" xyz="0 0 0"/>
      <mass value="0.40083918"/>
      <inertia ixx="0.00043534" ixy="+0.00000013" ixz="-0.00000002" iyy="0.00044549" iyz="+0.00000051" izz="0.00059634"/>
    </inertial>
  </link>
  <link name="indy1_tcp"/>
  <joint name="indy1_joint0" type="revolute">
    <parent link="indy1_link0"/>
    <child link="indy1_link1"/>
    <origin rpy="0 0 0" xyz="0 0 0.0775"/>
    <axis xyz="0 0 1"/>
    <limit effort="10" lower="-3.05432619099" upper="3.05432619099" velocity="1"/>
  </joint>
  <joint name="indy1_joint1" type="revolute">
    <parent link="indy1_link1"/>
    <child link="indy1_link2"/>
    <origin rpy="1.57079632679 1.57079632679 0" xyz="0 -0.10900000 0.22200000"/>
    <axis xyz="0 0 1"/>
    <limit effort="10" lower="-3.05432619099" upper="3.05432619099" velocity="1"/>
  </joint>
  <joint name="indy1_joint2" type="revolute">
    <parent link="indy1_link2"/>
    <child link="indy1_link3"/>
    <origin rpy="0 0 0" xyz="-0.45000000 +0.00000000 -0.03050000"/>
    <axis xyz="0 0 1"/>
    <limit effort="10" lower="-3.05432619099" upper="3.05432619099" velocity="1"/>
  </joint>
  <joint name="indy1_joint3" type="revolute">
    <parent link="indy1_link3"/>
    <child link="indy1_link4"/>
    <origin rpy="-1.57079632679 0 1.57079632679" xyz="-0.26700000 +0.00000000 -0.07500000"/>
    <axis xyz="0 0 1"/>
    <limit effort="10" lower="-3.05432619099" upper="3.05432619099" velocity="1"/>
  </joint>
  <joint name="indy1_joint4" type="revolute">
    <parent link="indy1_link4"/>
    <child link="indy1_link5"/>
    <origin rpy="1.57079632679 1.57079632679 0" xyz="+0.00000000 -0.11400000 +0.08300000"/>
    <axis xyz="0 0 1"/>
    <limit effort="10" lower="-3.05432619099" upper="3.05432619099" velocity="1"/>
  </joint>
  <joint name="indy1_joint5" type="revolute">
    <parent link="indy1_link5"/>
    <child link="indy1_link6"/>
    <origin rpy="-1.57079632679 0 1.57079632679" xyz="-0.16800000 +0.00000000 +0.06900000"/>
    <axis xyz="0 0 1"/>
    <limit effort="10" lower="-3.75245789179" upper="3.75245789179" velocity="1"/>
  </joint>
  <joint name="indy1_tcp" type="fixed">
    <parent link="indy1_link6"/>
    <child link="indy1_tcp"/>
    <origin rpy="0 0 0" xyz="0 0 0.06"/>
  </joint>
  <transmission name="indy1_tran0">
    <type>transmission_interface/SimpleTransmission</type>
    <joint name="indy1_joint0">
      <hardwareInterface>PositionJointInterface</hardwareInterface>
    </joint>
    <actuator name="indy1_motor0">
      <hardwareInterface>PositionJointInterface</hardwareInterface>
      <mechanicalReduction>1</mechanicalReduction>
    </actuator>
  </transmission>
  <transmission name="indy1_tran1">
    <type>transmission_interface/SimpleTransmission</type>
    <joint name="indy1_joint1">
      <hardwareInterface>PositionJointInterface</hardwareInterface>
    </joint>
    <actuator name="indy1_motor1">
      <hardwareInterface>PositionJointInterface</hardwareInterface>
      <mechanicalReduction>1</mechanicalReduction>
    </actuator>
  </transmission>
  <transmission name="indy1_tran2">
    <type>transmission_interface/SimpleTransmission</type>
    <joint name="indy1_joint2">
      <hardwareInterface>PositionJointInterface</hardwareInterface>
    </joint>
    <actuator name="indy1_motor2">
      <hardwareInterface>PositionJointInterface</hardwareInterface>
      <mechanicalReduction>1</mechanicalReduction>
    </actuator>
  </transmission>
  <transmission name="indy1_tran3">
    <type>transmission_interface/SimpleTransmission</type>
    <joint name="indy1_joint3">
      <hardwareInterface>PositionJointInterface</hardwareInterface>
    </joint>
    <actuator name="indy1_motor3">
      <hardwareInterface>PositionJointInterface</hardwareInterface>
      <mechanicalReduction>1</mechanicalReduction>
    </actuator>
  </transmission>
  <transmission name="indy1_tran4">
    <type>transmission_interface/SimpleTransmission</type>
    <joint name="indy1_joint4">
      <hardwareInterface>PositionJointInterface</hardwareInterface>
    </joint>
    <actuator name="indy1_motor4">
      <hardwareInterface>PositionJointInterface</hardwareInterface>
      <mechanicalReduction>1</mechanicalReduction>
    </actuator>
  </transmission>
  <transmission name="indy1_tran5">
    <type>transmission_interface/SimpleTransmission</type>
    <joint name="indy1_joint5">
      <hardwareInterface>PositionJointInterface</hardwareInterface>
    </joint>
    <actuator name="indy1_motor5">
      <hardwareInterface>PositionJointInterface</hardwareInterface>
      <mechanicalReduction>1</mechanicalReduction>
    </actuator>
  </transmission>
</robot>

